Workbook

Sheet 7-21
A1: Daily Production Log
B3: Job: | C3: SW Cheese | F3: Total Budgeted Hours: | G3: 4355 | H3: Total Job Days: | I3: 49 | N3: Lost Time Due to Weather | Q3: 1 Day | R3: 44702
B4: Project Number: | C4: 300155 | F4: Total Hours to Date: | G4: =N16+'6-30-22'!G4 -> 3402.5 | H4: No. of days to date: | I4: 47 | Q4: 1 Day | R4: 44732
B5: Date of Report | G5: =G4/G3 -> 0.78128588 | I5: =I4/I3 -> 0.95918367
A7: Personnel | C7: Name | E7: Hours | F7: Veh. No. | H7: Name | J7: Hours | L7: Name | N7: Hours | O7: Veh. No.
A8: 1 | B8: Super: | C8: JOHNSTON, B. (Walter) | F8: 66 | G8: 9 | H8: GONZALES, M. (Marcos) | K8: 17 | L8: Ketkeo Douanglamany -KK | O8: 83
A9: 2 | B9: Foreman: | C9: CRUZ, L. (Lucas) | G9: 10 | H9: Chanhorm Phaysakda | K9: 18 | L9: Max Chan Keomany | O9: 84
A10: 3 | B10: QC: | C10: *NIETO, M. (Mario) | F10: 78 | G10: 11 | H10: Vongsavanh Phaysakda | K10: 19 | L10: Boualaphanh Phanmaha | O10: 81
A11: 4 | B11: Techs: | C11: HERNANDEZ, B. (Bonofocio) | G11: 12 | H11: Thai Vilaboud | K11: 20 | L11: Khengkham Lovan Siriphom | O11: 79
A12: 5 | C12: ROMERO, J. (Jose) | G12: 13 | H12: Khamtanh Xaymonty | K12: 21 | L12: Soudsamay Phouthavong Lovan
A13: 6 | C13: *LOPEZ, J. (Jamie) | F13: 74 | G13: 14 | H13: Phichet Munwong | K13: 22
A14: 7 | C14: MORGAN, L (Luke) | G14: 15 | H14: Phouangsavanh Thammavongsa | K14: 23
A15: 8 | C15: NELCA, D. (Dennis) | G15: 16 | H15: Khamphone Sihavong | K15: 24
L16: TOTAL
B18: Description | C18: Total Sq Ft | D18: Sq. Ft. per Man Hour | E18: Sq. Ft. per Day | F18: No. Techs | G18: Hours | H18: No. Techs | I18: Hours | J18: Total Hours | K18: Actual Sq. Ft. per Hour | M18: Total Production for Job | N18: % | O18: Total Hours for Job | P18: Production Rate for Total Job
B20: MOB | C20: 1 | D20: 1 | G20: 0 | J20: =F20*G20+H20*I20 -> 0 | K20: =E20/(J20) -> #DIV/0! | M20: 0 | N20: =M20/C20 -> 0 | O20: =J20+'6-30-22'!O20 -> 108 | P20: =M20/O20 -> 0
B22: Remove Insulation Cover (SF) | C22: 125400 | J22: =F22*G22+H22*I22 -> 0 | K22: =E22/(J22) -> #DIV/0! | M22: =E22+'6-30-22'!M22 -> 125400 | N22: =M22/C22 -> 1 | O22: =J22+'6-30-22'!O22 -> 679.75 | P22: =M22/O22 -> 184.47959
B24: Remove Primary Cover (SF) | C24: 125400 | J24: =F24*G24+H24*I24 -> 0 | K24: =E24/(J24) -> #DIV/0! | M24: =E24+'6-30-22'!M24 -> 125400 | N24: =M24/C24 -> 1 | O24: =J24+'6-30-22'!O24 -> 449.75 | P24: =M24/O24 -> 278.82157
B26: Remove Existing Battens | C26: 3040 | J26: =F26*G26+H26*I26 -> 0 | K26: =E26/(J26) -> #DIV/0! | M26: =E26+'6-30-22'!M26 -> 3040 | N26: =M26/C26 -> 1 | O26: =J26+'6-30-22'!O26 -> 121.25 | P26: =M26/O26 -> 25.072165
B28: Installation New Batttens | C28: 3040 | J28: =F28*G28+H28*I28 -> 0 | K28: =E28/(J28) -> #DIV/0! | M28: =E28+'6-30-22'!M28 -> 2362 | N28: =M28/C28 -> 0.77697368 | O28: =J28+'6-30-22'!O28 -> 621.25 | P28: =M28/O28 -> 3.8020121
B30: Install 100 Mil Cover | C30: 123400 | J30: =F30*G30+H30*I30 -> 0 | K30: =E30/(J30) -> #DIV/0! | M30: =E30+'6-30-22'!M30 -> 123400 | N30: =M30/C30 -> 1 | O30: =J30+'6-30-22'!O30 -> 645.5 | P30: =M30/O30 -> 191.16964
B32: Patches & Straps | C32: 303 | J32: =F32*G32+H32*I32 -> 0 | K32: =E32/(J32) -> #DIV/0! | M32: =E32+'6-30-22'!M32 -> 303 | N32: =M32/C32 -> 1 | O32: =J32+'6-30-22'!O32 -> 166.5 | P32: =M32/O32 -> 1.8198198
B34: 60 Mil Cover & Foam | C34: 115000 | J34: =F34*G34+H34*I34 -> 0 | K34: =E34/(J34) -> #DIV/0! | M34: =E34+'6-30-22'!M34 -> 0 | N34: =M34/C34 -> 0 | O34: =J34+'6-30-22'!O34 -> 117 | P34: =M34/O34 -> 0
B36: Sample Ports | C36: 8 | J36: =F36*G36+H36*I36 -> 0 | K36: =E36/(J36) -> #DIV/0! | M36: =E36+'6-30-22'!M36 -> 8 | N36: =M36/C36 -> 1 | O36: =J36+'6-30-22'!O36 -> 69 | P36: =M36/O36 -> 0.11594203
B38: Ballast Pipes | C38: =2760+480 -> 3240 | J38: =F38*G38+H38*I38 -> 0 | K38: =E38/(J38) -> #DIV/0! | M38: =E38+'6-30-22'!M38 -> 1635 | N38: =M38/C38 -> 0.50462963 | O38: =J38+'6-30-22'!O38 -> 72 | P38: =M38/O38 -> 22.708333
B40: Grout (123/HR) | C40: 123 | J40: =F40*G40+H40*I40 -> 0 | K40: =E40/(J40) -> #DIV/0! | M40: =E40+'6-30-22'!M40 -> 0 | N40: =M40/C40 -> 0 | O40: =J40+'6-30-22'!O40 -> 0 | P40: =M40/O40 -> #DIV/0!
B42: Owner/Contractor Delay | J42: =F42*G42+H42*I42 -> 0 | K42: =E42/(J42) -> #DIV/0! | M42: =E42+'6-30-22'!M42 -> 0 | N42: =M42/C42 -> #VALUE! | O42: =J42+'6-30-22'!O42 -> 0 | P42: =M42/O42 -> #DIV/0!
B44: Work Outside Original Scope | J44: =F44*G44+H44*I44 -> 0 | K44: =E44/(J44) -> #DIV/0! | M44: =E44+'6-30-22'!M44 -> #VALUE! | N44: =M44/C44 -> #VALUE! | O44: =J44+'6-30-22'!O44 -> 99 | P44: =M44/O44 -> #VALUE!
B46: Weather Delay | J46: =F46*G46+H46*I46 -> 0 | K46: =E46/(J46) -> #DIV/0! | M46: =E46+'6-30-22'!M46 -> 0 | N46: =M46/C46 -> #DIV/0! | O46: =J46+'6-30-22'!O46 -> 253.5 | P46: =M46/O46 -> 0
B47: Total: | J47: =J20+J22+J24+J26+J28+J30+J32+J34+J36+J38+J40+J42+J44+J46 -> 0 | O47: =O20+O22+O24+O26+O28+O30+O32+O34+O36+O38+O40+O42+O44+O46 -> 3402.5
B49: NOTES:
B51: TEMP:
B53: WEATHER:

Sheet 7-10-22
A1: Daily Production Log
B3: Job: | C3: SW Cheese | F3: Total Budgeted Hours: | G3: 4355 | H3: Total Job Days: | I3: 49 | N3: Lost Time Due to Weather | Q3: 1 Day | R3: 44702
B4: Project Number: | C4: 300155 | F4: Total Hours to Date: | G4: =N16+'6-30-22'!G4 -> 3476.75 | H4: No. of days to date: | I4: 47 | Q4: 1 Day | R4: 44732
B5: Date of Report | G5: =G4/G3 -> 0.79833525 | I5: =I4/I3 -> 0.95918367
A7: Personnel | C7: Name | E7: Hours | F7: Veh. No. | H7: Name | J7: Hours | L7: Name | N7: Hours | O7: Veh. No.
A8: 1 | B8: Super: | C8: JOHNSTON, B. (Walter) | E8: 8.25 | F8: 66 | G8: 9 | H8: GONZALES, M. (Marcos) | J8: 8.25 | K8: 17 | L8: Ketkeo Douanglamany -KK | O8: 83
A9: 2 | B9: Foreman: | C9: CRUZ, L. (Lucas) | E9: 8.25 | G9: 10 | H9: Chanhorm Phaysakda | K9: 18 | L9: Max Chan Keomany | O9: 84
A10: 3 | B10: QC: | C10: *NIETO, M. (Mario) | E10: 8.25 | F10: 78 | G10: 11 | H10: Vongsavanh Phaysakda | K10: 19 | L10: Boualaphanh Phanmaha | O10: 81
A11: 4 | B11: Techs: | C11: HERNANDEZ, B. (Bonofocio) | E11: 8.25 | G11: 12 | H11: Thai Vilaboud | K11: 20 | L11: Khengkham Lovan Siriphom | O11: 79
A12: 5 | C12: ROMERO, J. (Jose) | E12: 8.25 | G12: 13 | H12: Khamtanh Xaymonty | K12: 21 | L12: Soudsamay Phouthavong Lovan
A13: 6 | C13: *LOPEZ, J. (Jamie) | E13: 8.25 | F13: 74 | G13: 14 | H13: Phichet Munwong | K13: 22
A14: 7 | C14: MORGAN, L (Luke) | E14: 8.25 | G14: 15 | H14: Phouangsavanh Thammavongsa | K14: 23
A15: 8 | C15: NELCA, D. (Dennis) | E15: 8.25 | G15: 16 | H15: Khamphone Sihavong | K15: 24
L16: TOTAL | N16: =E8+E9+E10+E11+E12+E13+E14+E15+J8+J9+J10+J11+J12+J13+J14+J15+N8+N9+N10+N11+N12+N13+N14+N15 -> 74.25
B18: Description | C18: Total Sq Ft | D18: Sq. Ft. per Man Hour | E18: Sq. Ft. per Day | F18: No. Techs | G18: Hours | H18: No. Techs | I18: Hours | J18: Total Hours | K18: Actual Sq. Ft. per Hour | M18: Total Production for Job | N18: % | O18: Total Hours for Job | P18: Production Rate for Total Job
B20: MOB | C20: 1 | D20: 1 | G20: 0 | J20: =F20*G20+H20*I20 -> 0 | K20: =E20/(J20) -> #DIV/0! | M20: 0 | N20: =M20/C20 -> 0 | O20: =J20+'6-30-22'!O20 -> 108 | P20: =M20/O20 -> 0
B22: Remove Insulation Cover (SF) | C22: 125400 | J22: =F22*G22+H22*I22 -> 0 | K22: =E22/(J22) -> #DIV/0! | M22: =E22+'6-30-22'!M22 -> 125400 | N22: =M22/C22 -> 1 | O22: =J22+'6-30-22'!O22 -> 679.75 | P22: =M22/O22 -> 184.47959
B24: Remove Primary Cover (SF) | C24: 125400 | J24: =F24*G24+H24*I24 -> 0 | K24: =E24/(J24) -> #DIV/0! | M24: =E24+'6-30-22'!M24 -> 125400 | N24: =M24/C24 -> 1 | O24: =J24+'6-30-22'!O24 -> 449.75 | P24: =M24/O24 -> 278.82157
B26: Remove Existing Battens | C26: 3040 | J26: =F26*G26+H26*I26 -> 0 | K26: =E26/(J26) -> #DIV/0! | M26: =E26+'6-30-22'!M26 -> 3040 | N26: =M26/C26 -> 1 | O26: =J26+'6-30-22'!O26 -> 121.25 | P26: =M26/O26 -> 25.072165
B28: Installation New Batttens | C28: 3040 | J28: =F28*G28+H28*I28 -> 0 | K28: =E28/(J28) -> #DIV/0! | M28: =E28+'6-30-22'!M28 -> 2362 | N28: =M28/C28 -> 0.77697368 | O28: =J28+'6-30-22'!O28 -> 621.25 | P28: =M28/O28 -> 3.8020121
B30: Install 100 Mil Cover | C30: 123400 | J30: =F30*G30+H30*I30 -> 0 | K30: =E30/(J30) -> #DIV/0! | M30: =E30+'6-30-22'!M30 -> 123400 | N30: =M30/C30 -> 1 | O30: =J30+'6-30-22'!O30 -> 645.5 | P30: =M30/O30 -> 191.16964
B32: Patches & Straps | C32: 303 | J32: =F32*G32+H32*I32 -> 0 | K32: =E32/(J32) -> #DIV/0! | M32: =E32+'6-30-22'!M32 -> 303 | N32: =M32/C32 -> 1 | O32: =J32+'6-30-22'!O32 -> 166.5 | P32: =M32/O32 -> 1.8198198
B34: 60 Mil Cover & Foam | C34: 115000 | D34: liner | E34: 5040 | F34: 9 | G34: 8.25 | J34: =F34*G34+H34*I34 -> 74.25 | K34: =E34/(J34) -> 67.878788 | M34: =E34+'6-30-22'!M34 -> 5040 | N34: =M34/C34 -> 0.043826087 | O34: =J34+'6-30-22'!O34 -> 191.25 | P34: =M34/O34 -> 26.352941
D35: foam | E35: 5040
B36: Sample Ports | C36: 8 | J36: =F36*G36+H36*I36 -> 0 | K36: =E36/(J36) -> #DIV/0! | M36: =E36+'6-30-22'!M36 -> 8 | N36: =M36/C36 -> 1 | O36: =J36+'6-30-22'!O36 -> 69 | P36: =M36/O36 -> 0.11594203
B38: Ballast Pipes | C38: =2760+480 -> 3240 | J38: =F38*G38+H38*I38 -> 0 | K38: =E38/(J38) -> #DIV/0! | M38: =E38+'6-30-22'!M38 -> 1635 | N38: =M38/C38 -> 0.50462963 | O38: =J38+'6-30-22'!O38 -> 72 | P38: =M38/O38 -> 22.708333
B40: Grout (123/HR) | C40: 123 | J40: =F40*G40+H40*I40 -> 0 | K40: =E40/(J40) -> #DIV/0! | M40: =E40+'6-30-22'!M40 -> 0 | N40: =M40/C40 -> 0 | O40: =J40+'6-30-22'!O40 -> 0 | P40: =M40/O40 -> #DIV/0!
B42: Owner/Contractor Delay | J42: =F42*G42+H42*I42 -> 0 | K42: =E42/(J42) -> #DIV/0! | M42: =E42+'6-30-22'!M42 -> 0 | N42: =M42/C42 -> #VALUE! | O42: =J42+'6-30-22'!O42 -> 0 | P42: =M42/O42 -> #DIV/0!
B44: Work Outside Original Scope | J44: =F44*G44+H44*I44 -> 0 | K44: =E44/(J44) -> #DIV/0! | M44: =E44+'6-30-22'!M44 -> #VALUE! | N44: =M44/C44 -> #VALUE! | O44: =J44+'6-30-22'!O44 -> 99 | P44: =M44/O44 -> #VALUE!
B46: Weather Delay | J46: =F46*G46+H46*I46 -> 0 | K46: =E46/(J46) -> #DIV/0! | M46: =E46+'6-30-22'!M46 -> 0 | N46: =M46/C46 -> #DIV/0! | O46: =J46+'6-30-22'!O46 -> 253.5 | P46: =M46/O46 -> 0
B47: Total: | J47: =J20+J22+J24+J26+J28+J30+J32+J34+J36+J38+J40+J42+J44+J46 -> 74.25 | O47: =O20+O22+O24+O26+O28+O30+O32+O34+O36+O38+O40+O42+O44+O46 -> 3476.75
B49: NOTES: | C49: EXT. WELDED 652 FT. DEPOLYED 5,040SF. LINER + 5040SF. FOAM
B51: TEMP: | C51: L - 69 H- 94
B53: WEATHER: | C53: HOT , MOSTLY SUNNY HIGHS IN THE UPPER 90s SOUTH WINDS AROUND 15 MPH

Sheet 7-9-22
A1: Daily Production Log
B3: Job: | C3: SW Cheese | F3: Total Budgeted Hours: | G3: 4355 | H3: Total Job Days: | I3: 49 | N3: Lost Time Due to Weather | Q3: 1 Day | R3: 44702
B4: Project Number: | C4: 300155 | F4: Total Hours to Date: | G4: =N16+'6-30-22'!G4 -> 3554.5 | H4: No. of days to date: | I4: 47 | Q4: 1 Day | R4: 44732
B5: Date of Report | G5: =G4/G3 -> 0.81618829 | I5: =I4/I3 -> 0.95918367
A7: Personnel | C7: Name | E7: Hours | F7: Veh. No. | H7: Name | J7: Hours | L7: Name | N7: Hours | O7: Veh. No.
A8: 1 | B8: Super: | C8: JOHNSTON, B. (Walter) | E8: 8 | F8: 66 | G8: 9 | H8: GONZALES, M. (Marcos) | J8: 8 | K8: 17 | L8: Ketkeo Douanglamany -KK | N8: 8 | O8: 83
A9: 2 | B9: Foreman: | C9: CRUZ, L. (Lucas) | E9: 8 | G9: 10 | H9: Chanhorm Phaysakda | J9: 8 | K9: 18 | L9: Max Chan Keomany | N9: 8 | O9: 84
A10: 3 | B10: QC: | C10: *NIETO, M. (Mario) | E10: 8 | F10: 78 | G10: 11 | H10: Vongsavanh Phaysakda | J10: 8 | K10: 19 | L10: Boualaphanh Phanmaha | N10: 8 | O10: 81
A11: 4 | B11: Techs: | C11: HERNANDEZ, B. (Bonofocio) | E11: 8 | G11: 12 | H11: Thai Vilaboud | J11: 8 | K11: 20 | L11: Khengkham Lovan Siriphom | N11: 8 | O11: 79
A12: 5 | C12: ROMERO, J. (Jose) | E12: 8 | G12: 13 | H12: Khamtanh Xaymonty | J12: 0 | K12: 21 | L12: Soudsamay Phouthavong Lovan | N12: 8
A13: 6 | C13: *LOPEZ, J. (Jamie) | E13: 8 | F13: 74 | G13: 14 | H13: Phichet Munwong | J13: 0 | K13: 22
A14: 7 | C14: MORGAN, L (Luke) | E14: 8 | G14: 15 | H14: Phouangsavanh Thammavongsa | J14: 8 | K14: 23
A15: 8 | C15: NELCA, D. (Dennis) | E15: 8 | G15: 16 | H15: Khamphone Sihavong | J15: 8 | K15: 24
L16: TOTAL | N16: =E8+E9+E10+E11+E12+E13+E14+E15+J8+J9+J10+J11+J12+J13+J14+J15+N8+N9+N10+N11+N12+N13+N14+N15 -> 152
B18: Description | C18: Total Sq Ft | D18: Sq. Ft. per Man Hour | E18: Sq. Ft. per Day | F18: No. Techs | G18: Hours | H18: No. Techs | I18: Hours | J18: Total Hours | K18: Actual Sq. Ft. per Hour | M18: Total Production for Job | N18: % | O18: Total Hours for Job | P18: Production Rate for Total Job
B20: MOB | C20: 1 | D20: 1 | G20: 0 | J20: =F20*G20+H20*I20 -> 0 | K20: =E20/(J20) -> #DIV/0! | M20: 0 | N20: =M20/C20 -> 0 | O20: =J20+'6-30-22'!O20 -> 108 | P20: =M20/O20 -> 0
B22: Remove Insulation Cover (SF) | C22: 125400 | J22: =F22*G22+H22*I22 -> 0 | K22: =E22/(J22) -> #DIV/0! | M22: =E22+'6-30-22'!M22 -> 125400 | N22: =M22/C22 -> 1 | O22: =J22+'6-30-22'!O22 -> 679.75 | P22: =M22/O22 -> 184.47959
B24: Remove Primary Cover (SF) | C24: 125400 | J24: =F24*G24+H24*I24 -> 0 | K24: =E24/(J24) -> #DIV/0! | M24: =E24+'6-30-22'!M24 -> 125400 | N24: =M24/C24 -> 1 | O24: =J24+'6-30-22'!O24 -> 449.75 | P24: =M24/O24 -> 278.82157
B26: Remove Existing Battens | C26: 3040 | J26: =F26*G26+H26*I26 -> 0 | K26: =E26/(J26) -> #DIV/0! | M26: =E26+'6-30-22'!M26 -> 3040 | N26: =M26/C26 -> 1 | O26: =J26+'6-30-22'!O26 -> 121.25 | P26: =M26/O26 -> 25.072165
B28: Installation New Batttens | C28: 3040 | J28: =F28*G28+H28*I28 -> 0 | K28: =E28/(J28) -> #DIV/0! | M28: =E28+'6-30-22'!M28 -> 2362 | N28: =M28/C28 -> 0.77697368 | O28: =J28+'6-30-22'!O28 -> 621.25 | P28: =M28/O28 -> 3.8020121
B30: Install 100 Mil Cover | C30: 123400 | J30: =F30*G30+H30*I30 -> 0 | K30: =E30/(J30) -> #DIV/0! | M30: =E30+'6-30-22'!M30 -> 123400 | N30: =M30/C30 -> 1 | O30: =J30+'6-30-22'!O30 -> 645.5 | P30: =M30/O30 -> 191.16964
B32: Patches & Straps | C32: 303 | J32: =F32*G32+H32*I32 -> 0 | K32: =E32/(J32) -> #DIV/0! | M32: =E32+'6-30-22'!M32 -> 303 | N32: =M32/C32 -> 1 | O32: =J32+'6-30-22'!O32 -> 166.5 | P32: =M32/O32 -> 1.8198198
B34: 60 Mil Cover & Foam | C34: 115000 | D34: liner | E34: 10080 | F34: 19 | G34: 8 | J34: =F34*G34+H34*I34 -> 152 | K34: =E34/(J34) -> 66.315789 | M34: =E34+'6-30-22'!M34 -> 10080 | N34: =M34/C34 -> 0.087652174 | O34: =J34+'6-30-22'!O34 -> 269 | P34: =M34/O34 -> 37.472119
D35: foam | E35: 10080
B36: Sample Ports | C36: 8 | J36: =F36*G36+H36*I36 -> 0 | K36: =E36/(J36) -> #DIV/0! | M36: =E36+'6-30-22'!M36 -> 8 | N36: =M36/C36 -> 1 | O36: =J36+'6-30-22'!O36 -> 69 | P36: =M36/O36 -> 0.11594203
B38: Ballast Pipes | C38: =2760+480 -> 3240 | J38: =F38*G38+H38*I38 -> 0 | K38: =E38/(J38) -> #DIV/0! | M38: =E38+'6-30-22'!M38 -> 1635 | N38: =M38/C38 -> 0.50462963 | O38: =J38+'6-30-22'!O38 -> 72 | P38: =M38/O38 -> 22.708333
B40: Grout (123/HR) | C40: 123 | J40: =F40*G40+H40*I40 -> 0 | K40: =E40/(J40) -> #DIV/0! | M40: =E40+'6-30-22'!M40 -> 0 | N40: =M40/C40 -> 0 | O40: =J40+'6-30-22'!O40 -> 0 | P40: =M40/O40 -> #DIV/0!
B42: Owner/Contractor Delay | J42: =F42*G42+H42*I42 -> 0 | K42: =E42/(J42) -> #DIV/0! | M42: =E42+'6-30-22'!M42 -> 0 | N42: =M42/C42 -> #VALUE! | O42: =J42+'6-30-22'!O42 -> 0 | P42: =M42/O42 -> #DIV/0!
B44: Work Outside Original Scope | J44: =F44*G44+H44*I44 -> 0 | K44: =E44/(J44) -> #DIV/0! | M44: =E44+'6-30-22'!M44 -> #VALUE! | N44: =M44/C44 -> #VALUE! | O44: =J44+'6-30-22'!O44 -> 99 | P44: =M44/O44 -> #VALUE!
B46: Weather Delay | J46: =F46*G46+H46*I46 -> 0 | K46: =E46/(J46) -> #DIV/0! | M46: =E46+'6-30-22'!M46 -> 0 | N46: =M46/C46 -> #DIV/0! | O46: =J46+'6-30-22'!O46 -> 253.5 | P46: =M46/O46 -> 0
B47: Total: | J47: =J20+J22+J24+J26+J28+J30+J32+J34+J36+J38+J40+J42+J44+J46 -> 152 | O47: =O20+O22+O24+O26+O28+O30+O32+O34+O36+O38+O40+O42+O44+O46 -> 3554.5
B49: NOTES: | C49: WXT.WELDED 978 FT. DEPOLYED 10,080 LINER + 10,080 FOAM
B51: TEMP: | C51: L - 68 H - 88
B53: WEATHER: | C53: MOSTLY SUNNY THIS MORNING THEN PARTLY CLOUDY WITH ISOLATED SHOWERS + THUNDERSTORMS THIS AFTERNOON
C54: HIGHS IN THE MID 90s SOUTHEAST WINDS AROUND 15 MPH THIS AFTERNOON CHANCE OF RAIN 20 PERCENT

Sheet 7-8-22
A1: Daily Production Log
B3: Job: | C3: SW Cheese | F3: Total Budgeted Hours: | G3: 4355 | H3: Total Job Days: | I3: 49 | N3: Lost Time Due to Weather | Q3: 1 Day | R3: 44702
B4: Project Number: | C4: 300155 | F4: Total Hours to Date: | G4: =N16+'6-30-22'!G4 -> 3583 | H4: No. of days to date: | I4: 47 | Q4: 1 Day | R4: 44732
B5: Date of Report | G5: =G4/G3 -> 0.82273249 | I5: =I4/I3 -> 0.95918367
A7: Personnel | C7: Name | E7: Hours | F7: Veh. No. | H7: Name | J7: Hours | L7: Name | N7: Hours | O7: Veh. No.
A8: 1 | B8: Super: | C8: JOHNSTON, B. (Walter) | E8: 9.5 | F8: 66 | G8: 9 | H8: GONZALES, M. (Marcos) | J8: 9.5 | K8: 17 | L8: Ketkeo Douanglamany -KK | N8: 9.5 | O8: 83
A9: 2 | B9: Foreman: | C9: CRUZ, L. (Lucas) | E9: 9.5 | G9: 10 | H9: Chanhorm Phaysakda | J9: 9.5 | K9: 18 | L9: Max Chan Keomany | N9: 9.5 | O9: 84
A10: 3 | B10: QC: | C10: *NIETO, M. (Mario) | E10: 9.5 | F10: 78 | G10: 11 | H10: Vongsavanh Phaysakda | J10: 9.5 | K10: 19 | L10: Boualaphanh Phanmaha | N10: 9.5 | O10: 81
A11: 4 | B11: Techs: | C11: HERNANDEZ, B. (Bonofocio) | E11: 9.5 | G11: 12 | H11: Thai Vilaboud | J11: 9.5 | K11: 20 | L11: Khengkham Lovan Siriphom | N11: 9.5 | O11: 79
A12: 5 | C12: ROMERO, J. (Jose) | E12: 9.5 | G12: 13 | H12: Khamtanh Xaymonty | J12: 0 | K12: 21 | L12: Soudsamay Phouthavong Lovan | N12: 9.5
A13: 6 | C13: *LOPEZ, J. (Jamie) | E13: 9.5 | F13: 74 | G13: 14 | H13: Phichet Munwong | J13: 0 | K13: 22
A14: 7 | C14: MORGAN, L (Luke) | E14: 9.5 | G14: 15 | H14: Phouangsavanh Thammavongsa | J14: 9.5 | K14: 23
A15: 8 | C15: NELCA, D. (Dennis) | E15: 9.5 | G15: 16 | H15: Khamphone Sihavong | J15: 9.5 | K15: 24
L16: TOTAL | N16: =E8+E9+E10+E11+E12+E13+E14+E15+J8+J9+J10+J11+J12+J13+J14+J15+N8+N9+N10+N11+N12+N13+N14+N15 -> 180.5
B18: Description | C18: Total Sq Ft | D18: Sq. Ft. per Man Hour | E18: Sq. Ft. per Day | F18: No. Techs | G18: Hours | H18: No. Techs | I18: Hours | J18: Total Hours | K18: Actual Sq. Ft. per Hour | M18: Total Production for Job | N18: % | O18: Total Hours for Job | P18: Production Rate for Total Job
B20: MOB | C20: 1 | D20: 1 | G20: 0 | J20: =F20*G20+H20*I20 -> 0 | K20: =E20/(J20) -> #DIV/0! | M20: 0 | N20: =M20/C20 -> 0 | O20: =J20+'6-30-22'!O20 -> 108 | P20: =M20/O20 -> 0
B22: Remove Insulation Cover (SF) | C22: 125400 | J22: =F22*G22+H22*I22 -> 0 | K22: =E22/(J22) -> #DIV/0! | M22: =E22+'6-30-22'!M22 -> 125400 | N22: =M22/C22 -> 1 | O22: =J22+'6-30-22'!O22 -> 679.75 | P22: =M22/O22 -> 184.47959
B24: Remove Primary Cover (SF) | C24: 125400 | J24: =F24*G24+H24*I24 -> 0 | K24: =E24/(J24) -> #DIV/0! | M24: =E24+'6-30-22'!M24 -> 125400 | N24: =M24/C24 -> 1 | O24: =J24+'6-30-22'!O24 -> 449.75 | P24: =M24/O24 -> 278.82157
B26: Remove Existing Battens | C26: 3040 | J26: =F26*G26+H26*I26 -> 0 | K26: =E26/(J26) -> #DIV/0! | M26: =E26+'6-30-22'!M26 -> 3040 | N26: =M26/C26 -> 1 | O26: =J26+'6-30-22'!O26 -> 121.25 | P26: =M26/O26 -> 25.072165
B28: Installation New Batttens | C28: 3040 | J28: =F28*G28+H28*I28 -> 0 | K28: =E28/(J28) -> #DIV/0! | M28: =E28+'6-30-22'!M28 -> 2362 | N28: =M28/C28 -> 0.77697368 | O28: =J28+'6-30-22'!O28 -> 621.25 | P28: =M28/O28 -> 3.8020121
B30: Install 100 Mil Cover | C30: 123400 | J30: =F30*G30+H30*I30 -> 0 | K30: =E30/(J30) -> #DIV/0! | M30: =E30+'6-30-22'!M30 -> 123400 | N30: =M30/C30 -> 1 | O30: =J30+'6-30-22'!O30 -> 645.5 | P30: =M30/O30 -> 191.16964
B32: Patches & Straps | C32: 303 | J32: =F32*G32+H32*I32 -> 0 | K32: =E32/(J32) -> #DIV/0! | M32: =E32+'6-30-22'!M32 -> 303 | N32: =M32/C32 -> 1 | O32: =J32+'6-30-22'!O32 -> 166.5 | P32: =M32/O32 -> 1.8198198
B34: 60 Mil Cover & Foam | C34: 115000 | D34: liner | E34: 15420 | F34: 19 | G34: 9.5 | J34: =F34*G34+H34*I34 -> 180.5 | K34: =E34/(J34) -> 85.429363 | M34: =E34+'6-30-22'!M34 -> 15420 | N34: =M34/C34 -> 0.13408696 | O34: =J34+'6-30-22'!O34 -> 297.5 | P34: =M34/O34 -> 51.831933
D35: foam | E35: 15420
B36: Sample Ports | C36: 8 | J36: =F36*G36+H36*I36 -> 0 | K36: =E36/(J36) -> #DIV/0! | M36: =E36+'6-30-22'!M36 -> 8 | N36: =M36/C36 -> 1 | O36: =J36+'6-30-22'!O36 -> 69 | P36: =M36/O36 -> 0.11594203
B38: Ballast Pipes | C38: =2760+480 -> 3240 | J38: =F38*G38+H38*I38 -> 0 | K38: =E38/(J38) -> #DIV/0! | M38: =E38+'6-30-22'!M38 -> 1635 | N38: =M38/C38 -> 0.50462963 | O38: =J38+'6-30-22'!O38 -> 72 | P38: =M38/O38 -> 22.708333
B40: Grout (123/HR) | C40: 123 | J40: =F40*G40+H40*I40 -> 0 | K40: =E40/(J40) -> #DIV/0! | M40: =E40+'6-30-22'!M40 -> 0 | N40: =M40/C40 -> 0 | O40: =J40+'6-30-22'!O40 -> 0 | P40: =M40/O40 -> #DIV/0!
B42: Owner/Contractor Delay | J42: =F42*G42+H42*I42 -> 0 | K42: =E42/(J42) -> #DIV/0! | M42: =E42+'6-30-22'!M42 -> 0 | N42: =M42/C42 -> #VALUE! | O42: =J42+'6-30-22'!O42 -> 0 | P42: =M42/O42 -> #DIV/0!
B44: Work Outside Original Scope | J44: =F44*G44+H44*I44 -> 0 | K44: =E44/(J44) -> #DIV/0! | M44: =E44+'6-30-22'!M44 -> #VALUE! | N44: =M44/C44 -> #VALUE! | O44: =J44+'6-30-22'!O44 -> 99 | P44: =M44/O44 -> #VALUE!
B46: Weather Delay | J46: =F46*G46+H46*I46 -> 0 | K46: =E46/(J46) -> #DIV/0! | M46: =E46+'6-30-22'!M46 -> 0 | N46: =M46/C46 -> #DIV/0! | O46: =J46+'6-30-22'!O46 -> 253.5 | P46: =M46/O46 -> 0
B47: Total: | J47: =J20+J22+J24+J26+J28+J30+J32+J34+J36+J38+J40+J42+J44+J46 -> 180.5 | O47: =O20+O22+O24+O26+O28+O30+O32+O34+O36+O38+O40+O42+O44+O46 -> 3583
B49: NOTES: | C49: EXT. WELDED 978 FT. DEPOLYED 15,420 LINER + 15,420 FOAM
B51: TEMP: | C51: L - 69 H - 95
B53: WEATHER: | C53: PARTLY CLOUDY THIS MORNING THEN MOSTLY CLOUDY WITH SCATTLED SHOWERS +THUNDERSTORMS
C54: THIS AFTERNOON HIGHS IN THE LOWER 90s SOUTHEAST WIND AROUND 15 MPH CHANCE OF RAIN 40 PERCENT

Sheet Sheet1

Sheet Sheet2

Sheet Sheet3

Sheet Sheet4

Sheet Sheet5

Sheet 7-1-22
A1: Daily Production Log
B3: Job: | C3: SW Cheese | F3: Total Budgeted Hours: | G3: 4355 | H3: Total Job Days: | I3: 49 | N3: Lost Time Due to Weather | Q3: 1 Day | R3: 44702
B4: Project Number: | C4: 300155 | F4: Total Hours to Date: | G4: =N16+'6-30-22'!G4 -> 3483.5 | H4: No. of days to date: | I4: 47 | Q4: 1 Day | R4: 44732
B5: Date of Report | C5: 44743 | G5: =G4/G3 -> 0.79988519 | I5: =I4/I3 -> 0.95918367
A7: Personnel | C7: Name | E7: Hours | F7: Veh. No. | H7: Name | J7: Hours | L7: Name | N7: Hours | O7: Veh. No.
A8: 1 | B8: Super: | C8: JOHNSTON, B. (Walter) | E8: 9 | F8: 66 | G8: 9 | H8: GONZALES, M. (Marcos) | J8: 9 | K8: 17 | L8: Ketkeo Douanglamany -KK | O8: 83
A9: 2 | B9: Foreman: | C9: CRUZ, L. (Lucas) | E9: 9 | G9: 10 | H9: Chanhorm Phaysakda | K9: 18 | L9: Max Chan Keomany | O9: 84
A10: 3 | B10: QC: | C10: *NIETO, M. (Mario) | E10: 9 | F10: 78 | G10: 11 | H10: Vongsavanh Phaysakda | K10: 19 | L10: Boualaphanh Phanmaha | O10: 81
A11: 4 | B11: Techs: | C11: HERNANDEZ, B. (Bonofocio) | E11: 9 | G11: 12 | H11: Thai Vilaboud | K11: 20 | L11: Khengkham Lovan Siriphom | O11: 79
A12: 5 | C12: ROMERO, J. (Jose) | E12: 9 | G12: 13 | H12: Khamtanh Xaymonty | K12: 21 | L12: Soudsamay Phouthavong Lovan
A13: 6 | C13: *LOPEZ, J. (Jamie) | E13: 9 | F13: 74 | G13: 14 | H13: Phichet Munwong | K13: 22
A14: 7 | C14: MORGAN, L (Luke) | E14: 9 | G14: 15 | H14: Phouangsavanh Thammavongsa | K14: 23
A15: 8 | C15: NELCA, D. (Dennis) | E15: 9 | G15: 16 | H15: Khamphone Sihavong | K15: 24
L16: TOTAL | N16: =E8+E9+E10+E11+E12+E13+E14+E15+J8+J9+J10+J11+J12+J13+J14+J15+N8+N9+N10+N11+N12+N13+N14+N15 -> 81
B18: Description | C18: Total Sq Ft | D18: Sq. Ft. per Man Hour | E18: Sq. Ft. per Day | F18: No. Techs | G18: Hours | H18: No. Techs | I18: Hours | J18: Total Hours | K18: Actual Sq. Ft. per Hour | M18: Total Production for Job | N18: % | O18: Total Hours for Job | P18: Production Rate for Total Job
B20: MOB | C20: 1 | D20: 1 | G20: 0 | J20: =F20*G20+H20*I20 -> 0 | K20: =E20/(J20) -> #DIV/0! | M20: 0 | N20: =M20/C20 -> 0 | O20: =J20+'6-30-22'!O20 -> 108 | P20: =M20/O20 -> 0
B22: Remove Insulation Cover (SF) | C22: 125400 | J22: =F22*G22+H22*I22 -> 0 | K22: =E22/(J22) -> #DIV/0! | M22: =E22+'6-30-22'!M22 -> 125400 | N22: =M22/C22 -> 1 | O22: =J22+'6-30-22'!O22 -> 679.75 | P22: =M22/O22 -> 184.47959
B24: Remove Primary Cover (SF) | C24: 125400 | J24: =F24*G24+H24*I24 -> 0 | K24: =E24/(J24) -> #DIV/0! | M24: =E24+'6-30-22'!M24 -> 125400 | N24: =M24/C24 -> 1 | O24: =J24+'6-30-22'!O24 -> 449.75 | P24: =M24/O24 -> 278.82157
B26: Remove Existing Battens | C26: 3040 | J26: =F26*G26+H26*I26 -> 0 | K26: =E26/(J26) -> #DIV/0! | M26: =E26+'6-30-22'!M26 -> 3040 | N26: =M26/C26 -> 1 | O26: =J26+'6-30-22'!O26 -> 121.25 | P26: =M26/O26 -> 25.072165
B28: Installation New Batttens | C28: 3040 | J28: =F28*G28+H28*I28 -> 0 | K28: =E28/(J28) -> #DIV/0! | M28: =E28+'6-30-22'!M28 -> 2362 | N28: =M28/C28 -> 0.77697368 | O28: =J28+'6-30-22'!O28 -> 621.25 | P28: =M28/O28 -> 3.8020121
B30: Install 100 Mil Cover | C30: 123400 | J30: =F30*G30+H30*I30 -> 0 | K30: =E30/(J30) -> #DIV/0! | M30: =E30+'6-30-22'!M30 -> 123400 | N30: =M30/C30 -> 1 | O30: =J30+'6-30-22'!O30 -> 645.5 | P30: =M30/O30 -> 191.16964
B32: Patches & Straps | C32: 303 | J32: =F32*G32+H32*I32 -> 0 | K32: =E32/(J32) -> #DIV/0! | M32: =E32+'6-30-22'!M32 -> 303 | N32: =M32/C32 -> 1 | O32: =J32+'6-30-22'!O32 -> 166.5 | P32: =M32/O32 -> 1.8198198
B34: 60 Mil Cover & Foam | C34: 115000 | E34: 4680 liner | F34: 9 | G34: 9 | J34: =F34*G34+H34*I34 -> 81 | K34: =E34/(J34) -> #VALUE! | M34: =E34+'6-30-22'!M34 -> #VALUE! | N34: =M34/C34 -> #VALUE! | O34: =J34+'6-30-22'!O34 -> 198 | P34: =M34/O34 -> #VALUE!
E35: 4680 foam
B36: Sample Ports | C36: 8 | J36: =F36*G36+H36*I36 -> 0 | K36: =E36/(J36) -> #DIV/0! | M36: =E36+'6-30-22'!M36 -> 8 | N36: =M36/C36 -> 1 | O36: =J36+'6-30-22'!O36 -> 69 | P36: =M36/O36 -> 0.11594203
B38: Ballast Pipes | C38: =2760+480 -> 3240 | J38: =F38*G38+H38*I38 -> 0 | K38: =E38/(J38) -> #DIV/0! | M38: =E38+'6-30-22'!M38 -> 1635 | N38: =M38/C38 -> 0.50462963 | O38: =J38+'6-30-22'!O38 -> 72 | P38: =M38/O38 -> 22.708333
B40: Grout (123/HR) | C40: 123 | J40: =F40*G40+H40*I40 -> 0 | K40: =E40/(J40) -> #DIV/0! | M40: =E40+'6-30-22'!M40 -> 0 | N40: =M40/C40 -> 0 | O40: =J40+'6-30-22'!O40 -> 0 | P40: =M40/O40 -> #DIV/0!
B42: Owner/Contractor Delay | J42: =F42*G42+H42*I42 -> 0 | K42: =E42/(J42) -> #DIV/0! | M42: =E42+'6-30-22'!M42 -> 0 | N42: =M42/C42 -> #VALUE! | O42: =J42+'6-30-22'!O42 -> 0 | P42: =M42/O42 -> #DIV/0!
B44: Work Outside Original Scope | J44: =F44*G44+H44*I44 -> 0 | K44: =E44/(J44) -> #DIV/0! | M44: =E44+'6-30-22'!M44 -> #VALUE! | N44: =M44/C44 -> #VALUE! | O44: =J44+'6-30-22'!O44 -> 99 | P44: =M44/O44 -> #VALUE!
B46: Weather Delay | J46: =F46*G46+H46*I46 -> 0 | K46: =E46/(J46) -> #DIV/0! | M46: =E46+'6-30-22'!M46 -> 0 | N46: =M46/C46 -> #DIV/0! | O46: =J46+'6-30-22'!O46 -> 253.5 | P46: =M46/O46 -> 0
B47: Total: | J47: =J20+J22+J24+J26+J28+J30+J32+J34+J36+J38+J40+J42+J44+J46 -> 81 | O47: =O20+O22+O24+O26+O28+O30+O32+O34+O36+O38+O40+O42+O44+O46 -> 3483.5
B49: NOTES: | C49: 4680 sqft 60 mil. Liner 4680 sqft foam will weld tomorrow morning | D49: 6830 sqft foam insl. Will welded 60 mil. Tomorrow
B51: TEMP: | C51: L - 69 H - 95
B53: WEATHER: | C53: MOSTLY SUNNY THIS MORNING THEN BECOMING PARTLY CLOUDY HIGHS IN THE 90s
C54: south winds around 15 mph

Sheet 6-30-22
A1: Daily Production Log
B3: Job: | C3: SW Cheese | F3: Total Budgeted Hours: | G3: 4355 | H3: Total Job Days: | I3: 49 | N3: Lost Time Due to Weather | Q3: 1 Day | R3: 44702
B4: Project Number: | C4: 300155 | F4: Total Hours to Date: | G4: =N16+'6-29-22'!G4 -> 3402.5 | H4: No. of days to date: | I4: 46 | Q4: 1 Day | R4: 44732
B5: Date of Report | C5: 44742 | G5: =G4/G3 -> 0.78128588 | I5: =I4/I3 -> 0.93877551
A7: Personnel | C7: Name | E7: Hours | F7: Veh. No. | H7: Name | J7: Hours | L7: Name | N7: Hours | O7: Veh. No.
A8: 1 | B8: Super: | C8: JOHNSTON, B. (Walter) | E8: 9 | F8: 66 | G8: 9 | H8: GONZALES, M. (Marcos) | J8: 9 | K8: 17 | L8: Ketkeo Douanglamany -KK | O8: 83
A9: 2 | B9: Foreman: | C9: CRUZ, L. (Lucas) | E9: 9 | G9: 10 | H9: Chanhorm Phaysakda | K9: 18 | L9: Max Chan Keomany | O9: 84
A10: 3 | B10: QC: | C10: *NIETO, M. (Mario) | E10: 9 | F10: 78 | G10: 11 | H10: Vongsavanh Phaysakda | K10: 19 | L10: Boualaphanh Phanmaha | O10: 81
A11: 4 | B11: Techs: | C11: HERNANDEZ, B. (Bonofocio) | E11: 9 | G11: 12 | H11: Thai Vilaboud | K11: 20 | L11: Khengkham Lovan Siriphom | O11: 79
A12: 5 | C12: ROMERO, J. (Jose) | E12: 9 | G12: 13 | H12: Khamtanh Xaymonty | K12: 21 | L12: Soudsamay Phouthavong Lovan
A13: 6 | C13: *LOPEZ, J. (Jamie) | E13: 9 | F13: 74 | G13: 14 | H13: Phichet Munwong | K13: 22
A14: 7 | C14: MORGAN, L (Luke) | E14: 9 | G14: 15 | H14: Phouangsavanh Thammavongsa | K14: 23
A15: 8 | C15: NELCA, D. (Dennis) | E15: 9 | G15: 16 | H15: Khamphone Sihavong | K15: 24
L16: TOTAL | N16: =E8+E9+E10+E11+E12+E13+E14+E15+J8+J9+J10+J11+J12+J13+J14+J15+N8+N9+N10+N11+N12+N13+N14+N15 -> 81
B18: Description | C18: Total Sq Ft | D18: Sq. Ft. per Man Hour | E18: Sq. Ft. per Day | F18: No. Techs | G18: Hours | H18: No. Techs | I18: Hours | J18: Total Hours | K18: Actual Sq. Ft. per Hour | M18: Total Production for Job | N18: % | O18: Total Hours for Job | P18: Production Rate for Total Job
B20: MOB | C20: 1 | D20: 1 | G20: 0 | J20: =F20*G20+H20*I20 -> 0 | K20: =E20/(J20) -> #DIV/0! | M20: 0 | N20: =M20/C20 -> 0 | O20: =J20+'6-29-22'!O20 -> 108 | P20: =M20/O20 -> 0
B22: Remove Insulation Cover (SF) | C22: 125400 | J22: =F22*G22+H22*I22 -> 0 | K22: =E22/(J22) -> #DIV/0! | M22: =E22+'6-29-22'!M22 -> 125400 | N22: =M22/C22 -> 1 | O22: =J22+'6-29-22'!O22 -> 679.75 | P22: =M22/O22 -> 184.47959
B24: Remove Primary Cover (SF) | C24: 125400 | J24: =F24*G24+H24*I24 -> 0 | K24: =E24/(J24) -> #DIV/0! | M24: =E24+'6-29-22'!M24 -> 125400 | N24: =M24/C24 -> 1 | O24: =J24+'6-29-22'!O24 -> 449.75 | P24: =M24/O24 -> 278.82157
B26: Remove Existing Battens | C26: 3040 | J26: =F26*G26+H26*I26 -> 0 | K26: =E26/(J26) -> #DIV/0! | M26: =E26+'6-29-22'!M26 -> 3040 | N26: =M26/C26 -> 1 | O26: =J26+'6-29-22'!O26 -> 121.25 | P26: =M26/O26 -> 25.072165
B28: Installation New Batttens | C28: 3040 | E28: 200 | F28: 9 | G28: 6 | J28: =F28*G28+H28*I28 -> 54 | K28: =E28/(J28) -> 3.7037037 | M28: =E28+'6-29-22'!M28 -> 2362 | N28: =M28/C28 -> 0.77697368 | O28: =J28+'6-29-22'!O28 -> 621.25 | P28: =M28/O28 -> 3.8020121
B30: Install 100 Mil Cover | C30: 123400 | J30: =F30*G30+H30*I30 -> 0 | K30: =E30/(J30) -> #DIV/0! | M30: =E30+'6-29-22'!M30 -> 123400 | N30: =M30/C30 -> 1 | O30: =J30+'6-29-22'!O30 -> 645.5 | P30: =M30/O30 -> 191.16964
B32: Patches & Straps | C32: 303 | J32: =F32*G32+H32*I32 -> 0 | K32: =E32/(J32) -> #DIV/0! | M32: =E32+'6-29-22'!M32 -> 303 | N32: =M32/C32 -> 1 | O32: =J32+'6-29-22'!O32 -> 166.5 | P32: =M32/O32 -> 1.8198198
B34: 60 Mil Cover & Foam | C34: 115000 | D34: Burn Holes | F34: 9 | G34: 3 | J34: =F34*G34+H34*I34 -> 27 | K34: =E34/(J34) -> 0 | M34: =E34+'6-29-22'!M34 -> 0 | N34: =M34/C34 -> 0 | O34: =J34+'6-29-22'!O34 -> 117 | P34: =M34/O34 -> 0
D35: In Foam 210
B36: Sample Ports | C36: 8 | J36: =F36*G36+H36*I36 -> 0 | K36: =E36/(J36) -> #DIV/0! | M36: =E36+'6-29-22'!M36 -> 8 | N36: =M36/C36 -> 1 | O36: =J36+'6-29-22'!O36 -> 69 | P36: =M36/O36 -> 0.11594203
B38: Ballast Pipes | C38: =2760+480 -> 3240 | J38: =F38*G38+H38*I38 -> 0 | K38: =E38/(J38) -> #DIV/0! | M38: =E38+'6-29-22'!M38 -> 1635 | N38: =M38/C38 -> 0.50462963 | O38: =J38+'6-29-22'!O38 -> 72 | P38: =M38/O38 -> 22.708333
B40: Grout (123/HR) | C40: 123 | J40: =F40*G40+H40*I40 -> 0 | K40: =E40/(J40) -> #DIV/0! | M40: =E40+'6-29-22'!M40 -> 0 | N40: =M40/C40 -> 0 | O40: =J40+'6-29-22'!O40 -> 0 | P40: =M40/O40 -> #DIV/0!
B42: Owner/Contractor Delay | J42: =F42*G42+H42*I42 -> 0 | K42: =E42/(J42) -> #DIV/0! | M42: =E42+'6-29-22'!M42 -> 0 | N42: =M42/C42 -> #VALUE! | O42: =J42+'6-29-22'!O42 -> 0 | P42: =M42/O42 -> #DIV/0!
B44: Work Outside Original Scope | J44: =F44*G44+H44*I44 -> 0 | K44: =E44/(J44) -> #DIV/0! | M44: =E44+'6-29-22'!M44 -> #VALUE! | N44: =M44/C44 -> #VALUE! | O44: =J44+'6-29-22'!O44 -> 99 | P44: =M44/O44 -> #VALUE!
B46: Weather Delay | J46: =F46*G46+H46*I46 -> 0 | K46: =E46/(J46) -> #DIV/0! | M46: =E46+'6-29-22'!M46 -> 0 | N46: =M46/C46 -> #DIV/0! | O46: =J46+'6-29-22'!O46 -> 253.5 | P46: =M46/O46 -> 0
B47: Total: | J47: =J20+J22+J24+J26+J28+J30+J32+J34+J36+J38+J40+J42+J44+J46 -> 81 | O47: =O20+O22+O24+O26+O28+O30+O32+O34+O36+O38+O40+O42+O44+O46 -> 3402.5
B49: NOTES: | C49: BURNED HOLES IN FOAM (210 HOLES ) SET GASKET + EPOXY + ANCHOR BOLTS
B51: TEMP: | C51: L -64 H - 93
B53: WEATHER: | C53: BREEZY HOT MOSTLY SUNNY HIGH IN THE 90s SOUTHWEST WINDS 15 TO 25 MPH

Sheet 6-29-22
A1: Daily Production Log
B3: Job: | C3: SW Cheese | F3: Total Budgeted Hours: | G3: 4355 | H3: Total Job Days: | I3: 49 | N3: Lost Time Due to Weather | Q3: 1 Day | R3: 44702
B4: Project Number: | C4: 300155 | F4: Total Hours to Date: | G4: =J16+'6-28-22'!G4 -> 3321.5 | H4: No. of days to date: | I4: 45 | Q4: 1 Day | R4: 44732
B5: Date of Report | C5: 44741 | G5: =G4/G3 -> 0.76268657 | I5: =I4/I3 -> 0.91836735
A7: Personnel | C7: Name | E7: Hours | F7: Veh. No. | H7: Name | J7: Hours
A8: 1 | B8: Super: | C8: JOHNSTON, B. (Walter) | E8: 9 | F8: 66 | G8: 9 | H8: GONZALES, M. (Marcos) | J8: 9
A9: 2 | B9: Foreman: | C9: CRUZ, L. (Lucas) | E9: 9 | G9: 10
A10: 3 | B10: QC: | C10: *NIETO, M. (Mario) | E10: 9 | F10: 78 | G10: 11
A11: 4 | B11: Techs: | C11: HERNANDEZ, B. (Bonofocio) | E11: 9 | G11: 12
A12: 5 | C12: ROMERO, J. (Jose) | E12: 9 | G12: 13
A13: 6 | C13: *LOPEZ, J. (Jamie) | E13: 9 | F13: 74 | G13: 14
A14: 7 | C14: MORGAN, L (Luke) | E14: 9 | G14: 15
A15: 8 | C15: NELCA, D. (Dennis) | E15: 9 | G15: 16
H16: TOTAL | J16: =SUM(E8:E15)+SUM(J8:J15) -> 81
B18: Description | C18: Total Sq Ft | D18: Sq. Ft. per Man Hour | E18: Sq. Ft. per Day | F18: No. Techs | G18: Hours | H18: No. Techs | I18: Hours | J18: Total Hours | K18: Actual Sq. Ft. per Hour | M18: Total Production for Job | N18: % | O18: Total Hours for Job | P18: Production Rate for Total Job
B20: MOB | C20: 1 | D20: 1 | G20: 0 | J20: =F20*G20+H20*I20 -> 0 | K20: =E20/(J20) -> #DIV/0! | M20: 0 | N20: =M20/C20 -> 0 | O20: =J20+'6-28-22'!O20 -> 108 | P20: =M20/O20 -> 0
B22: Remove Insulation Cover (SF) | C22: 125400 | J22: =F22*G22+H22*I22 -> 0 | K22: =E22/(J22) -> #DIV/0! | M22: =E22+'6-28-22'!M22 -> 125400 | N22: =M22/C22 -> 1 | O22: =J22+'6-28-22'!O22 -> 679.75 | P22: =M22/O22 -> 184.47959
B24: Remove Primary Cover (SF) | C24: 125400 | J24: =F24*G24+H24*I24 -> 0 | K24: =E24/(J24) -> #DIV/0! | M24: =E24+'6-28-22'!M24 -> 125400 | N24: =M24/C24 -> 1 | O24: =J24+'6-28-22'!O24 -> 449.75 | P24: =M24/O24 -> 278.82157
B26: Remove Existing Battens | C26: 3040 | J26: =F26*G26+H26*I26 -> 0 | K26: =E26/(J26) -> #DIV/0! | M26: =E26+'6-28-22'!M26 -> 3040 | N26: =M26/C26 -> 1 | O26: =J26+'6-28-22'!O26 -> 121.25 | P26: =M26/O26 -> 25.072165
B28: Installation New Batttens | C28: 3040 | E28: 285 | F28: 9 | G28: 6 | J28: =F28*G28+H28*I28 -> 54 | K28: =E28/(J28) -> 5.2777778 | M28: =E28+'6-28-22'!M28 -> 2162 | N28: =M28/C28 -> 0.71118421 | O28: =J28+'6-28-22'!O28 -> 567.25 | P28: =M28/O28 -> 3.8113706
B30: Install 100 Mil Cover | C30: 123400 | J30: =F30*G30+H30*I30 -> 0 | K30: =E30/(J30) -> #DIV/0! | M30: =E30+'6-28-22'!M30 -> 123400 | N30: =M30/C30 -> 1 | O30: =J30+'6-28-22'!O30 -> 645.5 | P30: =M30/O30 -> 191.16964
B32: Patches & Straps | C32: 303 | J32: =F32*G32+H32*I32 -> 0 | K32: =E32/(J32) -> #DIV/0! | M32: =E32+'6-28-22'!M32 -> 303 | N32: =M32/C32 -> 1 | O32: =J32+'6-28-22'!O32 -> 166.5 | P32: =M32/O32 -> 1.8198198
B34: 60 Mil Cover & Foam | C34: 115000 | D34: Burned Holes | F34: 9 | G34: 3 | J34: =F34*G34+H34*I34 -> 27 | K34: =E34/(J34) -> 0 | M34: =E34+'6-28-22'!M34 -> 0 | N34: =M34/C34 -> 0 | O34: =J34+'6-28-22'!O34 -> 90 | P34: =M34/O34 -> 0
D35: In Foam
B36: Sample Ports | C36: 8 | J36: =F36*G36+H36*I36 -> 0 | K36: =E36/(J36) -> #DIV/0! | M36: =E36+'6-28-22'!M36 -> 8 | N36: =M36/C36 -> 1 | O36: =J36+'6-28-22'!O36 -> 69 | P36: =M36/O36 -> 0.11594203
B38: Ballast Pipes | C38: =2760+480 -> 3240 | J38: =F38*G38+H38*I38 -> 0 | K38: =E38/(J38) -> #DIV/0! | M38: =E38+'6-28-22'!M38 -> 1635 | N38: =M38/C38 -> 0.50462963 | O38: =J38+'6-28-22'!O38 -> 72 | P38: =M38/O38 -> 22.708333
B40: Grout (123/HR) | C40: 123 | J40: =F40*G40+H40*I40 -> 0 | K40: =E40/(J40) -> #DIV/0! | M40: =E40+'6-28-22'!M40 -> 0 | N40: =M40/C40 -> 0 | O40: =J40+'6-28-22'!O40 -> 0 | P40: =M40/O40 -> #DIV/0!
B42: Owner/Contractor Delay | J42: =F42*G42+H42*I42 -> 0 | K42: =E42/(J42) -> #DIV/0! | M42: =E42+'6-28-22'!M42 -> 0 | N42: =M42/C42 -> #VALUE! | O42: =J42+'6-28-22'!O42 -> 0 | P42: =M42/O42 -> #DIV/0!
B44: Work Outside Original Scope | J44: =F44*G44+H44*I44 -> 0 | K44: =E44/(J44) -> #DIV/0! | M44: =E44+'6-28-22'!M44 -> #VALUE! | N44: =M44/C44 -> #VALUE! | O44: =J44+'6-28-22'!O44 -> 99 | P44: =M44/O44 -> #VALUE!
B46: Weather Delay | J46: =F46*G46+H46*I46 -> 0 | K46: =E46/(J46) -> #DIV/0! | M46: =E46+'6-28-22'!M46 -> 0 | N46: =M46/C46 -> #DIV/0! | O46: =J46+'6-27-22'!O46 -> 253.5 | P46: =M46/O46 -> 0
B47: Total: | J47: =J20+J22+J24+J26+J28+J30+J32+J34+J36+J38+J40+J42+J44+J46 -> 81 | O47: =O20+O22+O24+O26+O28+O30+O32+O34+O36+O38+O40+O42+O44+O46 -> 3321.5
B49: NOTES: | C49: BURNED HOLES IN FOAM 180 PCS 285 FT. GASKET + EPOXY + ANCHOR BOLTS
B51: TEMP: | C51: L -64 H - 88
B53: WEATHER: | C53: MOSTLY SUNNY HIGHS IN THE UPPER 80s SOUTHWEST WINDS AROUND 15 MPH

Sheet 6-28-22
A1: Daily Production Log
B3: Job: | C3: SW Cheese | F3: Total Budgeted Hours: | G3: 4355 | H3: Total Job Days: | I3: 49 | N3: Lost Time Due to Weather | Q3: 1 Day | R3: 44702
B4: Project Number: | C4: 300155 | F4: Total Hours to Date: | G4: =J16+'6-27-22'!G4 -> 3240.5 | H4: No. of days to date: | I4: 44 | Q4: 1 Day | R4: 44732
B5: Date of Report | C5: 44740 | G5: =G4/G3 -> 0.74408726 | I5: =I4/I3 -> 0.89795918
A7: Personnel | C7: Name | E7: Hours | F7: Veh. No. | H7: Name | J7: Hours
A8: 1 | B8: Super: | C8: JOHNSTON, B. (Walter) | E8: 9 | F8: 66 | G8: 9 | H8: GONZALES, M. (Marcos) | J8: 9
A9: 2 | B9: Foreman: | C9: CRUZ, L. (Lucas) | E9: 9 | G9: 10
A10: 3 | B10: QC: | C10: *NIETO, M. (Mario) | E10: 9 | F10: 78 | G10: 11
A11: 4 | B11: Techs: | C11: HERNANDEZ, B. (Bonofocio) | E11: 9 | G11: 12
A12: 5 | C12: ROMERO, J. (Jose) | E12: 9 | G12: 13
A13: 6 | C13: *LOPEZ, J. (Jamie) | E13: 9 | F13: 74 | G13: 14
A14: 7 | C14: MORGAN, L (Luke) | E14: 9 | G14: 15
A15: 8 | C15: NELCA, D. (Dennis) | E15: 9 | G15: 16
H16: TOTAL | J16: =SUM(E8:E15)+SUM(J8:J15) -> 81
B18: Description | C18: Total Sq Ft | D18: Sq. Ft. per Man Hour | E18: Sq. Ft. per Day | F18: No. Techs | G18: Hours | H18: No. Techs | I18: Hours | J18: Total Hours | K18: Actual Sq. Ft. per Hour | M18: Total Production for Job | N18: % | O18: Total Hours for Job | P18: Production Rate for Total Job
B20: MOB | C20: 1 | D20: 1 | G20: 0 | J20: =F20*G20+H20*I20 -> 0 | K20: =E20/(J20) -> #DIV/0! | M20: 0 | N20: =M20/C20 -> 0 | O20: =J20+'6-27-22'!O20 -> 108 | P20: =M20/O20 -> 0
B22: Remove Insulation Cover (SF) | C22: 125400 | J22: =F22*G22+H22*I22 -> 0 | K22: =E22/(J22) -> #DIV/0! | M22: =E22+'6-27-22'!M22 -> 125400 | N22: =M22/C22 -> 1 | O22: =J22+'6-27-22'!O22 -> 679.75 | P22: =M22/O22 -> 184.47959
B24: Remove Primary Cover (SF) | C24: 125400 | J24: =F24*G24+H24*I24 -> 0 | K24: =E24/(J24) -> #DIV/0! | M24: =E24+'6-27-22'!M24 -> 125400 | N24: =M24/C24 -> 1 | O24: =J24+'6-27-22'!O24 -> 449.75 | P24: =M24/O24 -> 278.82157
B26: Remove Existing Battens | C26: 3040 | J26: =F26*G26+H26*I26 -> 0 | K26: =E26/(J26) -> #DIV/0! | M26: =E26+'6-27-22'!M26 -> 3040 | N26: =M26/C26 -> 1 | O26: =J26+'6-27-22'!O26 -> 121.25 | P26: =M26/O26 -> 25.072165
B28: Installation New Batttens | C28: 3040 | E28: 330 | F28: 9 | G28: 6 | J28: =F28*G28+H28*I28 -> 54 | K28: =E28/(J28) -> 6.1111111 | M28: =E28+'6-27-22'!M28 -> 1877 | N28: =M28/C28 -> 0.61743421 | O28: =J28+'6-27-22'!O28 -> 513.25 | P28: =M28/O28 -> 3.6570872
B30: Install 100 Mil Cover | C30: 123400 | J30: =F30*G30+H30*I30 -> 0 | K30: =E30/(J30) -> #DIV/0! | M30: =E30+'6-27-22'!M30 -> 123400 | N30: =M30/C30 -> 1 | O30: =J30+'6-27-22'!O30 -> 645.5 | P30: =M30/O30 -> 191.16964
B32: Patches & Straps | C32: 303 | J32: =F32*G32+H32*I32 -> 0 | K32: =E32/(J32) -> #DIV/0! | M32: =E32+'6-27-22'!M32 -> 303 | N32: =M32/C32 -> 1 | O32: =J32+'6-27-22'!O32 -> 166.5 | P32: =M32/O32 -> 1.8198198
B34: 60 Mil Cover & Foam | C34: 115000 | F34: 9 | G34: 3 | J34: =F34*G34+H34*I34 -> 27 | K34: =E34/(J34) -> 0 | M34: =E34+'6-27-22'!M34 -> 0 | N34: =M34/C34 -> 0 | O34: =J34+'6-27-22'!O34 -> 63 | P34: =M34/O34 -> 0
B36: Sample Ports | C36: 8 | J36: =F36*G36+H36*I36 -> 0 | K36: =E36/(J36) -> #DIV/0! | M36: =E36+'6-27-22'!M36 -> 8 | N36: =M36/C36 -> 1 | O36: =J36+'6-27-22'!O36 -> 69 | P36: =M36/O36 -> 0.11594203
B38: Ballast Pipes | C38: =2760+480 -> 3240 | J38: =F38*G38+H38*I38 -> 0 | K38: =E38/(J38) -> #DIV/0! | M38: =E38+'6-27-22'!M38 -> 1635 | N38: =M38/C38 -> 0.50462963 | O38: =J38+'6-27-22'!O38 -> 72 | P38: =M38/O38 -> 22.708333
B40: Grout (123/HR) | C40: 123 | J40: =F40*G40+H40*I40 -> 0 | K40: =E40/(J40) -> #DIV/0! | M40: =E40+'6-27-22'!M40 -> 0 | N40: =M40/C40 -> 0 | O40: =J40+'6-27-22'!O40 -> 0 | P40: =M40/O40 -> #DIV/0!
B42: Owner/Contractor Delay | J42: =F42*G42+H42*I42 -> 0 | K42: =E42/(J42) -> #DIV/0! | M42: =E42+'6-27-22'!M42 -> 0 | N42: =M42/C42 -> #VALUE! | O42: =J42+'6-27-22'!O42 -> 0 | P42: =M42/O42 -> #DIV/0!
B44: Work Outside Original Scope | J44: =F44*G44+H44*I44 -> 0 | K44: =E44/(J44) -> #DIV/0! | M44: =E44+'6-27-22'!M44 -> #VALUE! | N44: =M44/C44 -> #VALUE! | O44: =J44+'6-27-22'!O44 -> 99 | P44: =M44/O44 -> #VALUE!
B46: Weather Delay | J46: =F46*G46+H46*I46 -> 0 | K46: =E46/(J46) -> #DIV/0! | M46: =E46+'6-27-22'!M46 -> 0 | N46: =M46/C46 -> #DIV/0! | O46: =J46+'6-27-22'!O46 -> 253.5 | P46: =M46/O46 -> 0
B47: Total: | J47: =J20+J22+J24+J26+J28+J30+J32+J34+J36+J38+J40+J42+J44+J46 -> 81 | O47: =O20+O22+O24+O26+O28+O30+O32+O34+O36+O38+O40+O42+O44+O46 -> 3240.5
B49: NOTES: | C49: BURNED HOLES 155 PC.OF FOAM SET 330FT. OF GASKET + EPOXY + ANCHOR BOLTS
B51: TEMP: | C51: L -65 H - 82
B53: WEATHER: | C53: MOSTLY CLOUDY THIS THEN BECOMING PARTLY CLOUDY SLIGHT CHANCE OF SHOWERS +THUNDERSTORMS HIGHS IN THE 80s
C54: SOUTH WINDS AROUND 15 THIS AFTERNOON CHANCE OF RAIN 20 PERCENT

Sheet 6-27-22
A1: Daily Production Log
B3: Job: | C3: SW Cheese | F3: Total Budgeted Hours: | G3: 4355 | H3: Total Job Days: | I3: 49 | N3: Lost Time Due to Weather | Q3: 1 Day | R3: 44702
B4: Project Number: | C4: 300155 | F4: Total Hours to Date: | G4: =J16+'6-26-22'!G4 -> 3159.5 | H4: No. of days to date: | I4: 43 | Q4: 1 Day | R4: 44732
B5: Date of Report | C5: 44739 | G5: =G4/G3 -> 0.72548794 | I5: =I4/I3 -> 0.87755102
A7: Personnel | C7: Name | E7: Hours | F7: Veh. No. | H7: Name | J7: Hours
A8: 1 | B8: Super: | C8: JOHNSTON, B. (Walter) | E8: 9.5 | F8: 66 | G8: 9 | H8: GONZALES, M. (Marcos) | J8: 9.5
A9: 2 | B9: Foreman: | C9: CRUZ, L. (Lucas) | E9: 9.5 | G9: 10
A10: 3 | B10: QC: | C10: *NIETO, M. (Mario) | E10: 9.5 | F10: 78 | G10: 11
A11: 4 | B11: Techs: | C11: HERNANDEZ, B. (Bonofocio) | E11: 9.5 | G11: 12
A12: 5 | C12: ROMERO, J. (Jose) | E12: 9.5 | G12: 13
A13: 6 | C13: *LOPEZ, J. (Jamie) | E13: 9.5 | F13: 74 | G13: 14
A14: 7 | C14: MORGAN, L (Luke) | E14: 9.5 | G14: 15
A15: 8 | C15: NELCA, D. (Dennis) | E15: 9.5 | G15: 16
H16: TOTAL | J16: =SUM(E8:E15)+SUM(J8:J15) -> 85.5
B18: Description | C18: Total Sq Ft | D18: Sq. Ft. per Man Hour | E18: Sq. Ft. per Day | F18: No. Techs | G18: Hours | H18: No. Techs | I18: Hours | J18: Total Hours | K18: Actual Sq. Ft. per Hour | M18: Total Production for Job | N18: % | O18: Total Hours for Job | P18: Production Rate for Total Job
B20: MOB | C20: 1 | D20: 1 | G20: 0 | J20: =F20*G20+H20*I20 -> 0 | K20: =E20/(J20) -> #DIV/0! | M20: 0 | N20: =M20/C20 -> 0 | O20: =J20+'6-26-22'!O20 -> 108 | P20: =M20/O20 -> 0
B22: Remove Insulation Cover (SF) | C22: 125400 | J22: =F22*G22+H22*I22 -> 0 | K22: =E22/(J22) -> #DIV/0! | M22: =E22+'6-26-22'!M22 -> 125400 | N22: =M22/C22 -> 1 | O22: =J22+'6-26-22'!O22 -> 679.75 | P22: =M22/O22 -> 184.47959
B24: Remove Primary Cover (SF) | C24: 125400 | J24: =F24*G24+H24*I24 -> 0 | K24: =E24/(J24) -> #DIV/0! | M24: =E24+'6-26-22'!M24 -> 125400 | N24: =M24/C24 -> 1 | O24: =J24+'6-26-22'!O24 -> 449.75 | P24: =M24/O24 -> 278.82157
B26: Remove Existing Battens | C26: 3040 | E26: 1524 | J26: =F26*G26+H26*I26 -> 0 | K26: =E26/(J26) -> #DIV/0! | M26: =E26+'6-26-22'!M26 -> 3040 | N26: =M26/C26 -> 1 | O26: =J26+'6-26-22'!O26 -> 121.25 | P26: =M26/O26 -> 25.072165
B28: Installation New Batttens | C28: 3040 | E28: 243 | F28: 9 | G28: 5.5 | J28: =F28*G28+H28*I28 -> 49.5 | K28: =E28/(J28) -> 4.9090909 | M28: =E28+'6-26-22'!M28 -> 1547 | N28: =M28/C28 -> 0.50888158 | O28: =J28+'6-26-22'!O28 -> 459.25 | P28: =M28/O28 -> 3.3685357
B30: Install 100 Mil Cover | C30: 123400 | J30: =F30*G30+H30*I30 -> 0 | K30: =E30/(J30) -> #DIV/0! | M30: =E30+'6-26-22'!M30 -> 123400 | N30: =M30/C30 -> 1 | O30: =J30+'6-26-22'!O30 -> 645.5 | P30: =M30/O30 -> 191.16964
B32: Patches & Straps | C32: 303 | J32: =F32*G32+H32*I32 -> 0 | K32: =E32/(J32) -> #DIV/0! | M32: =E32+'6-26-22'!M32 -> 303 | N32: =M32/C32 -> 1 | O32: =J32+'6-26-22'!O32 -> 166.5 | P32: =M32/O32 -> 1.8198198
B34: 60 Mil Cover & Foam | C34: 115000 | D34: Burned holes | F34: 9 | G34: 4 | J34: =F34*G34+H34*I34 -> 36 | K34: =E34/(J34) -> 0 | M34: =E34+'6-26-22'!M34 -> 0 | N34: =M34/C34 -> 0 | O34: =J34+'6-26-22'!O34 -> 36 | P34: =M34/O34 -> 0
D35: in foam
B36: Sample Ports | C36: 8 | J36: =F36*G36+H36*I36 -> 0 | K36: =E36/(J36) -> #DIV/0! | M36: =E36+'6-26-22'!M36 -> 8 | N36: =M36/C36 -> 1 | O36: =J36+'6-26-22'!O36 -> 69 | P36: =M36/O36 -> 0.11594203
B38: Ballast Pipes | C38: =2760+480 -> 3240 | J38: =F38*G38+H38*I38 -> 0 | K38: =E38/(J38) -> #DIV/0! | M38: =E38+'6-26-22'!M38 -> 1635 | N38: =M38/C38 -> 0.50462963 | O38: =J38+'6-26-22'!O38 -> 72 | P38: =M38/O38 -> 22.708333
B40: Grout (123/HR) | C40: 123 | J40: =F40*G40+H40*I40 -> 0 | K40: =E40/(J40) -> #DIV/0! | M40: =E40+'6-26-22'!M40 -> 0 | N40: =M40/C40 -> 0 | O40: =J40+'6-26-22'!O40 -> 0 | P40: =M40/O40 -> #DIV/0!
B42: Owner/Contractor Delay | J42: =F42*G42+H42*I42 -> 0 | K42: =E42/(J42) -> #DIV/0! | M42: =E42+'6-26-22'!M42 -> 0 | N42: =M42/C42 -> #VALUE! | O42: =J42+'6-26-22'!O42 -> 0 | P42: =M42/O42 -> #DIV/0!
B44: Work Outside Original Scope | J44: =F44*G44+H44*I44 -> 0 | K44: =E44/(J44) -> #DIV/0! | M44: =E44+'6-26-22'!M44 -> #VALUE! | N44: =M44/C44 -> #VALUE! | O44: =J44+'6-26-22'!O44 -> 99 | P44: =M44/O44 -> #VALUE!
B46: Weather Delay | J46: =F46*G46+H46*I46 -> 0 | K46: =E46/(J46) -> #DIV/0! | M46: =E46+'6-26-22'!M46 -> 0 | N46: =M46/C46 -> #DIV/0! | O46: =J46+'6-26-22'!O46 -> 253.5 | P46: =M46/O46 -> 0
B47: Total: | J47: =J20+J22+J24+J26+J28+J30+J32+J34+J36+J38+J40+J42+J44+J46 -> 85.5 | O47: =O20+O22+O24+O26+O28+O30+O32+O34+O36+O38+O40+O42+O44+O46 -> 3159.5
B49: NOTES: | C49: BURNED HOLES IN FOAM + SET GASKET +EPOXY + ANCHOR BOLTS
B51: TEMP: | C51: L -59 H -82
B53: WEATHER: | C53: MOSTLY CLOUDY WITH SCATTERED SHOWERS WINDS 15 TO 25 MPH

Sheet 6-26-22
A1: Daily Production Log
B3: Job: | C3: SW Cheese | F3: Total Budgeted Hours: | G3: 4355 | H3: Total Job Days: | I3: 49 | N3: Lost Time Due to Weather | Q3: 1 Day | R3: 44702
B4: Project Number: | C4: 300155 | F4: Total Hours to Date: | G4: =J16+'6-25-22'!G4 -> 3074 | H4: No. of days to date: | I4: 42 | Q4: 1 Day | R4: 44732
B5: Date of Report | C5: 44738 | G5: =G4/G3 -> 0.70585534 | I5: =I4/I3 -> 0.85714286
A7: Personnel | C7: Name | E7: Hours | F7: Veh. No. | H7: Name | J7: Hours
A8: 1 | B8: Super: | C8: JOHNSTON, B. (Walter) | E8: 8 | F8: 66 | G8: 9 | H8: GONZALES, M. (Marcos) | J8: 8
A9: 2 | B9: Foreman: | C9: CRUZ, L. (Lucas) | E9: 8 | G9: 10
A10: 3 | B10: QC: | C10: *NIETO, M. (Mario) | E10: 8 | F10: 78 | G10: 11
A11: 4 | B11: Techs: | C11: HERNANDEZ, B. (Bonofocio) | E11: 8 | G11: 12
A12: 5 | C12: ROMERO, J. (Jose) | E12: 8 | G12: 13
A13: 6 | C13: *LOPEZ, J. (Jamie) | E13: 8 | F13: 74 | G13: 14
A14: 7 | C14: MORGAN, L (Luke) | E14: 8 | G14: 15
A15: 8 | C15: NELCA, D. (Dennis) | E15: 8 | G15: 16
H16: TOTAL | J16: =SUM(E8:E15)+SUM(J8:J15) -> 72
B18: Description | C18: Total Sq Ft | D18: Sq. Ft. per Man Hour | E18: Sq. Ft. per Day | F18: No. Techs | G18: Hours | H18: No. Techs | I18: Hours | J18: Total Hours | K18: Actual Sq. Ft. per Hour | M18: Total Production for Job | N18: % | O18: Total Hours for Job | P18: Production Rate for Total Job
B20: MOB | C20: 1 | D20: 1 | G20: 0 | J20: =F20*G20+H20*I20 -> 0 | K20: =E20/(J20) -> #DIV/0! | M20: 0 | N20: =M20/C20 -> 0 | O20: =J20+'6-25-22'!O20 -> 108 | P20: =M20/O20 -> 0
B22: Remove Insulation Cover (SF) | C22: 125400 | J22: =F22*G22+H22*I22 -> 0 | K22: =E22/(J22) -> #DIV/0! | M22: =E22+'6-25-22'!M22 -> 125400 | N22: =M22/C22 -> 1 | O22: =J22+'6-25-22'!O22 -> 679.75 | P22: =M22/O22 -> 184.47959
B24: Remove Primary Cover (SF) | C24: 125400 | J24: =F24*G24+H24*I24 -> 0 | K24: =E24/(J24) -> #DIV/0! | M24: =E24+'6-25-22'!M24 -> 125400 | N24: =M24/C24 -> 1 | O24: =J24+'6-25-22'!O24 -> 449.75 | P24: =M24/O24 -> 278.82157
B26: Remove Existing Battens | C26: 3040 | J26: =F26*G26+H26*I26 -> 0 | K26: =E26/(J26) -> #DIV/0! | M26: =E26+'6-25-22'!M26 -> 1516 | N26: =M26/C26 -> 0.49868421 | O26: =J26+'6-25-22'!O26 -> 121.25 | P26: =M26/O26 -> 12.503093
B28: Installation New Batttens | C28: 3040 | E28: 303 | F28: 9 | G28: 8 | J28: =F28*G28+H28*I28 -> 72 | K28: =E28/(J28) -> 4.2083333 | M28: =E28+'6-25-22'!M28 -> 1304 | N28: =M28/C28 -> 0.42894737 | O28: =J28+'6-25-22'!O28 -> 409.75 | P28: =M28/O28 -> 3.1824283
B30: Install 100 Mil Cover | C30: 125400 | J30: =F30*G30+H30*I30 -> 0 | K30: =E30/(J30) -> #DIV/0! | M30: =E30+'6-25-22'!M30 -> 123400 | N30: =M30/C30 -> 0.98405104 | O30: =J30+'6-25-22'!O30 -> 645.5 | P30: =M30/O30 -> 191.16964
B32: Patches & Straps | C32: 303 | J32: =F32*G32+H32*I32 -> 0 | K32: =E32/(J32) -> #DIV/0! | M32: =E32+'6-25-22'!M32 -> 303 | N32: =M32/C32 -> 1 | O32: =J32+'6-25-22'!O32 -> 166.5 | P32: =M32/O32 -> 1.8198198
B34: 60 Mil Cover & Foam | C34: 115000 | J34: =F34*G34+H34*I34 -> 0 | K34: =E34/(J34) -> #DIV/0! | M34: =E34+'6-25-22'!M34 -> 0 | N34: =M34/C34 -> 0 | O34: =J34+'6-25-22'!O34 -> 0 | P34: =M34/O34 -> #DIV/0!
B36: Sample Ports | C36: 8 | J36: =F36*G36+H36*I36 -> 0 | K36: =E36/(J36) -> #DIV/0! | M36: =E36+'6-25-22'!M36 -> 8 | N36: =M36/C36 -> 1 | O36: =J36+'6-25-22'!O36 -> 69 | P36: =M36/O36 -> 0.11594203
B38: Ballast Pipes | C38: =2760+480 -> 3240 | J38: =F38*G38+H38*I38 -> 0 | K38: =E38/(J38) -> #DIV/0! | M38: =E38+'6-25-22'!M38 -> 1635 | N38: =M38/C38 -> 0.50462963 | O38: =J38+'6-25-22'!O38 -> 72 | P38: =M38/O38 -> 22.708333
B40: Grout (123/HR) | C40: 123 | J40: =F40*G40+H40*I40 -> 0 | K40: =E40/(J40) -> #DIV/0! | M40: =E40+'6-25-22'!M40 -> 0 | N40: =M40/C40 -> 0 | O40: =J40+'6-25-22'!O40 -> 0 | P40: =M40/O40 -> #DIV/0!
B42: Owner/Contractor Delay | J42: =F42*G42+H42*I42 -> 0 | K42: =E42/(J42) -> #DIV/0! | M42: =E42+'6-25-22'!M42 -> 0 | N42: =M42/C42 -> #VALUE! | O42: =J42+'6-25-22'!O42 -> 0 | P42: =M42/O42 -> #DIV/0!
B44: Work Outside Original Scope | J44: =F44*G44+H44*I44 -> 0 | K44: =E44/(J44) -> #DIV/0! | M44: =E44+'6-25-22'!M44 -> #VALUE! | N44: =M44/C44 -> #VALUE! | O44: =J44+'6-25-22'!O44 -> 99 | P44: =M44/O44 -> #VALUE!
B46: Weather Delay | J46: =F46*G46+H46*I46 -> 0 | K46: =E46/(J46) -> #DIV/0! | M46: =E46+'6-25-22'!M46 -> 0 | N46: =M46/C46 -> #DIV/0! | O46: =J46+'6-25-22'!O46 -> 253.5 | P46: =M46/O46 -> 0
B47: Total: | J47: =J20+J22+J24+J26+J28+J30+J32+J34+J36+J38+J40+J42+J44+J46 -> 72 | O47: =O20+O22+O24+O26+O28+O30+O32+O34+O36+O38+O40+O42+O44+O46 -> 3074
B49: NOTES: | C49: 303 FT. GASKET + | D49: EPOXY + ANCHOR BOLTS
B51: TEMP: | C51: L -63 H-72
B53: WEATHER: | C53: BREEZY MUCH COOLER MOSTLY CLOUDY ISOLATED SHOWERS THIS MORNING THEN SCATTERED SHOWERS THIS AFTERNOON HIGHS IN
C54: THE LOWERS 70s NORTHEAST WINDS 15 TO 25 CHANCE OF RAIN 30 PERCENT

Sheet 6-25-22
A1: Daily Production Log
B3: Job: | C3: SW Cheese | F3: Total Budgeted Hours: | G3: 4355 | H3: Total Job Days: | I3: 49 | N3: Lost Time Due to Weather | Q3: 1 Day | R3: 44702
B4: Project Number: | C4: 300155 | F4: Total Hours to Date: | G4: =J16+'6-24-22'!G4 -> 3002 | H4: No. of days to date: | I4: 41 | Q4: 1 Day | R4: 44732
B5: Date of Report | C5: 44737 | G5: =G4/G3 -> 0.68932262 | I5: =I4/I3 -> 0.83673469
A7: Personnel | C7: Name | E7: Hours | F7: Veh. No. | H7: Name | J7: Hours
A8: 1 | B8: Super: | C8: JOHNSTON, B. (Walter) | E8: 8 | F8: 66 | G8: 9 | H8: GONZALES, M. (Marcos) | J8: 8
A9: 2 | B9: Foreman: | C9: CRUZ, L. (Lucas) | E9: 8 | G9: 10
A10: 3 | B10: QC: | C10: *NIETO, M. (Mario) | E10: 8 | F10: 78 | G10: 11
A11: 4 | B11: Techs: | C11: HERNANDEZ, B. (Bonofocio) | E11: 8 | G11: 12
A12: 5 | C12: ROMERO, J. (Jose) | E12: 8 | G12: 13
A13: 6 | C13: *LOPEZ, J. (Jamie) | E13: 8 | F13: 74 | G13: 14
A14: 7 | C14: MORGAN, L (Luke) | E14: 8 | G14: 15
A15: 8 | C15: NELCA, D. (Dennis) | E15: 8 | G15: 16
H16: TOTAL | J16: =SUM(E8:E15)+SUM(J8:J15) -> 72
B18: Description | C18: Total Sq Ft | D18: Sq. Ft. per Man Hour | E18: Sq. Ft. per Day | F18: No. Techs | G18: Hours | H18: No. Techs | I18: Hours | J18: Total Hours | K18: Actual Sq. Ft. per Hour | M18: Total Production for Job | N18: % | O18: Total Hours for Job | P18: Production Rate for Total Job
B20: MOB | C20: 1 | D20: 1 | G20: 0 | J20: =F20*G20+H20*I20 -> 0 | K20: =E20/(J20) -> #DIV/0! | M20: 0 | N20: =M20/C20 -> 0 | O20: =J20+'6-24-22'!O20 -> 108 | P20: =M20/O20 -> 0
B22: Remove Insulation Cover (SF) | C22: 125400 | J22: =F22*G22+H22*I22 -> 0 | K22: =E22/(J22) -> #DIV/0! | M22: =E22+'6-24-22'!M22 -> 125400 | N22: =M22/C22 -> 1 | O22: =J22+'6-24-22'!O22 -> 679.75 | P22: =M22/O22 -> 184.47959
B24: Remove Primary Cover (SF) | C24: 125400 | J24: =F24*G24+H24*I24 -> 0 | K24: =E24/(J24) -> #DIV/0! | M24: =E24+'6-24-22'!M24 -> 125400 | N24: =M24/C24 -> 1 | O24: =J24+'6-24-22'!O24 -> 449.75 | P24: =M24/O24 -> 278.82157
B26: Remove Existing Battens | C26: 3040 | J26: =F26*G26+H26*I26 -> 0 | K26: =E26/(J26) -> #DIV/0! | M26: =E26+'6-24-22'!M26 -> 1516 | N26: =M26/C26 -> 0.49868421 | O26: =J26+'6-24-22'!O26 -> 121.25 | P26: =M26/O26 -> 12.503093
B28: Installation New Batttens | C28: 3040 | E28: 148 | F28: 9 | G28: 3 | J28: =F28*G28+H28*I28 -> 27 | K28: =E28/(J28) -> 5.4814815 | M28: =E28+'6-24-22'!M28 -> 1001 | N28: =M28/C28 -> 0.32927632 | O28: =J28+'6-24-22'!O28 -> 337.75 | P28: =M28/O28 -> 2.9637306
B30: Install 100 Mil Cover | C30: 125400 | J30: =F30*G30+H30*I30 -> 0 | K30: =E30/(J30) -> #DIV/0! | M30: =E30+'6-24-22'!M30 -> 123400 | N30: =M30/C30 -> 0.98405104 | O30: =J30+'6-24-22'!O30 -> 645.5 | P30: =M30/O30 -> 191.16964
B32: Patches & Straps | C32: 303 | J32: =F32*G32+H32*I32 -> 0 | K32: =E32/(J32) -> #DIV/0! | M32: =E32+'6-24-22'!M32 -> 303 | N32: =M32/C32 -> 1 | O32: =J32+'6-24-22'!O32 -> 166.5 | P32: =M32/O32 -> 1.8198198
B34: 60 Mil Cover & Foam | C34: 115000 | J34: =F34*G34+H34*I34 -> 0 | K34: =E34/(J34) -> #DIV/0! | M34: =E34+'6-24-22'!M34 -> 0 | N34: =M34/C34 -> 0 | O34: =J34+'6-24-22'!O34 -> 0 | P34: =M34/O34 -> #DIV/0!
B36: Sample Ports | C36: 8 | D36: 1 Emergency | E36: 8 | F36: 9 | G36: 5 | J36: =F36*G36+H36*I36 -> 45 | K36: =E36/(J36) -> 0.17777778 | M36: =E36+'6-24-22'!M36 -> 8 | N36: =M36/C36 -> 1 | O36: =J36+'6-24-22'!O36 -> 69 | P36: =M36/O36 -> 0.11594203
D37: Vent
B38: Ballast Pipes | C38: =2760+480 -> 3240 | J38: =F38*G38+H38*I38 -> 0 | K38: =E38/(J38) -> #DIV/0! | M38: =E38+'6-24-22'!M38 -> 1635 | N38: =M38/C38 -> 0.50462963 | O38: =J38+'6-24-22'!O38 -> 72 | P38: =M38/O38 -> 22.708333
B40: Grout (123/HR) | C40: 123 | J40: =F40*G40+H40*I40 -> 0 | K40: =E40/(J40) -> #DIV/0! | M40: =E40+'6-24-22'!M40 -> 0 | N40: =M40/C40 -> 0 | O40: =J40+'6-24-22'!O40 -> 0 | P40: =M40/O40 -> #DIV/0!
B42: Owner/Contractor Delay | J42: =F42*G42+H42*I42 -> 0 | K42: =E42/(J42) -> #DIV/0! | M42: =E42+'6-24-22'!M42 -> 0 | N42: =M42/C42 -> #VALUE! | O42: =J42+'6-24-22'!O42 -> 0 | P42: =M42/O42 -> #DIV/0!
B44: Work Outside Original Scope | J44: =F44*G44+H44*I44 -> 0 | K44: =E44/(J44) -> #DIV/0! | M44: =E44+'6-24-22'!M44 -> #VALUE! | N44: =M44/C44 -> #VALUE! | O44: =J44+'6-24-22'!O44 -> 99 | P44: =M44/O44 -> #VALUE!
B46: Weather Delay | J46: =F46*G46+H46*I46 -> 0 | K46: =E46/(J46) -> #DIV/0! | M46: =E46+'6-24-22'!M46 -> 0 | N46: =M46/C46 -> #DIV/0! | O46: =J46+'6-24-22'!O46 -> 253.5 | P46: =M46/O46 -> 0
B47: Total: | J47: =J20+J22+J24+J26+J28+J30+J32+J34+J36+J38+J40+J42+J44+J46 -> 72 | O47: =O20+O22+O24+O26+O28+O30+O32+O34+O36+O38+O40+O42+O44+O46 -> 3002
B49: NOTES: | C49: INSTALLED 8 SAMPLE PORT + 1 6"EMERGENCY VENT ON EAST SIDE 148 FT.
C50: GASKET +EPOXY + ANCHOR BOLTS
B51: TEMP: | C51: L -67 H -91
B53: WEATHER: | C53: BREEZY MOSTLY SUNNY THIS MORNING THEN MOSTLY CLOUDY WITH SCATTERED SHOWER +THUNDERSTOMS THIS AFTERNOON
C54: HIGHS IN THE 90 s SOUTHWEST WINDS 15 TO 20 BECOMING EAST 20 TO25 THIS AFTERNOON CHANCE OF RAIN 50 PERCENT

Sheet 6-24-22
A1: Daily Production Log
B3: Job: | C3: SW Cheese | F3: Total Budgeted Hours: | G3: 4355 | H3: Total Job Days: | I3: 49 | N3: Lost Time Due to Weather | Q3: 1 Day | R3: 44702
B4: Project Number: | C4: 300155 | F4: Total Hours to Date: | G4: =J16+'6-23-22'!G4 -> 2930 | H4: No. of days to date: | I4: 40 | Q4: 1 Day | R4: 44732
B5: Date of Report | C5: 44736 | G5: =G4/G3 -> 0.6727899 | I5: =I4/I3 -> 0.81632653
A7: Personnel | C7: Name | E7: Hours | F7: Veh. No. | H7: Name | J7: Hours
A8: 1 | B8: Super: | C8: JOHNSTON, B. (Walter) | E8: 9 | F8: 66 | G8: 9 | H8: GONZALES, M. (Marcos) | J8: 9
A9: 2 | B9: Foreman: | C9: CRUZ, L. (Lucas) | E9: 9 | G9: 10
A10: 3 | B10: QC: | C10: *NIETO, M. (Mario) | E10: 9 | F10: 78 | G10: 11
A11: 4 | B11: Techs: | C11: HERNANDEZ, B. (Bonofocio) | E11: 9 | G11: 12
A12: 5 | C12: ROMERO, J. (Jose) | E12: 9 | G12: 13
A13: 6 | C13: *LOPEZ, J. (Jamie) | E13: 9 | F13: 74 | G13: 14
A14: 7 | C14: MORGAN, L (Luke) | E14: 9 | G14: 15
A15: 8 | C15: NELCA, D. (Dennis) | E15: 9 | G15: 16
H16: TOTAL | J16: =SUM(E8:E15)+SUM(J8:J15) -> 81
B18: Description | C18: Total Sq Ft | D18: Sq. Ft. per Man Hour | E18: Sq. Ft. per Day | F18: No. Techs | G18: Hours | H18: No. Techs | I18: Hours | J18: Total Hours | K18: Actual Sq. Ft. per Hour | M18: Total Production for Job | N18: % | O18: Total Hours for Job | P18: Production Rate for Total Job
B20: MOB | C20: 1 | D20: 1 | G20: 0 | J20: =F20*G20+H20*I20 -> 0 | K20: =E20/(J20) -> #DIV/0! | M20: 0 | N20: =M20/C20 -> 0 | O20: =J20+'6-23-22'!O20 -> 108 | P20: =M20/O20 -> 0
B22: Remove Insulation Cover (SF) | C22: 125400 | J22: =F22*G22+H22*I22 -> 0 | K22: =E22/(J22) -> #DIV/0! | M22: =E22+'6-23-22'!M22 -> 125400 | N22: =M22/C22 -> 1 | O22: =J22+'6-23-22'!O22 -> 679.75 | P22: =M22/O22 -> 184.47959
B24: Remove Primary Cover (SF) | C24: 125400 | J24: =F24*G24+H24*I24 -> 0 | K24: =E24/(J24) -> #DIV/0! | M24: =E24+'6-23-22'!M24 -> 125400 | N24: =M24/C24 -> 1 | O24: =J24+'6-23-22'!O24 -> 449.75 | P24: =M24/O24 -> 278.82157
B26: Remove Existing Battens | C26: 3040 | J26: =F26*G26+H26*I26 -> 0 | K26: =E26/(J26) -> #DIV/0! | M26: =E26+'6-23-22'!M26 -> 1516 | N26: =M26/C26 -> 0.49868421 | O26: =J26+'6-23-22'!O26 -> 121.25 | P26: =M26/O26 -> 12.503093
B28: Installation New Batttens | C28: 3040 | J28: =F28*G28+H28*I28 -> 0 | K28: =E28/(J28) -> #DIV/0! | M28: =E28+'6-23-22'!M28 -> 853 | N28: =M28/C28 -> 0.28059211 | O28: =J28+'6-23-22'!O28 -> 310.75 | P28: =M28/O28 -> 2.7449718
B30: Install 100 Mil Cover | C30: 125400 | J30: =F30*G30+H30*I30 -> 0 | K30: =E30/(J30) -> #DIV/0! | M30: =E30+'6-23-22'!M30 -> 123400 | N30: =M30/C30 -> 0.98405104 | O30: =J30+'6-23-22'!O30 -> 645.5 | P30: =M30/O30 -> 191.16964
B32: Patches & Straps | C32: 324 | E32: 138 | F32: 9 | G32: 9 | J32: =F32*G32+H32*I32 -> 81 | K32: =E32/(J32) -> 1.7037037 | M32: =E32+'6-23-22'!M32 -> 303 | N32: =M32/C32 -> 0.93518519 | O32: =J32+'6-23-22'!O32 -> 166.5 | P32: =M32/O32 -> 1.8198198
B34: 60 Mil Cover & Foam | C34: 115000 | J34: =F34*G34+H34*I34 -> 0 | K34: =E34/(J34) -> #DIV/0! | M34: =E34+'6-23-22'!M34 -> 0 | N34: =M34/C34 -> 0 | O34: =J34+'6-23-22'!O34 -> 0 | P34: =M34/O34 -> #DIV/0!
B36: Sample Ports | C36: 8 | J36: =F36*G36+H36*I36 -> 0 | K36: =E36/(J36) -> #DIV/0! | M36: =E36+'6-23-22'!M36 -> 0 | N36: =M36/C36 -> 0 | O36: =J36+'6-23-22'!O36 -> 24 | P36: =M36/O36 -> 0
B38: Ballast Pipes | C38: =2760+480 -> 3240 | J38: =F38*G38+H38*I38 -> 0 | K38: =E38/(J38) -> #DIV/0! | M38: =E38+'6-23-22'!M38 -> 1635 | N38: =M38/C38 -> 0.50462963 | O38: =J38+'6-23-22'!O38 -> 72 | P38: =M38/O38 -> 22.708333
